2021-11-19 17:49:48,560 INFO    MainThread:84563 [internal.py:wandb_internal():91] W&B internal server running at pid: 84563, started at: 2021-11-19 17:49:48.560382
2021-11-19 17:49:48,562 DEBUG   HandlerThread:84563 [handler.py:handle_request():120] handle_request: check_version
2021-11-19 17:49:48,562 INFO    WriterThread:84563 [datastore.py:open_for_write():77] open: /home/mansour/Music/OtherWork/TextBPN/wandb/run-20211119_174948-20qk9gpt/run-20qk9gpt.wandb
2021-11-19 17:49:48,563 DEBUG   SenderThread:84563 [sender.py:send():160] send: header
2021-11-19 17:49:48,563 DEBUG   SenderThread:84563 [sender.py:send():160] send: request
2021-11-19 17:49:48,563 DEBUG   SenderThread:84563 [sender.py:send_request():169] send_request: check_version
2021-11-19 17:49:53,565 DEBUG   SenderThread:84563 [sender.py:send():160] send: run
2021-11-19 17:50:23,181 DEBUG   HandlerThread:84563 [handler.py:handle_request():120] handle_request: shutdown
2021-11-19 17:50:23,182 INFO    HandlerThread:84563 [handler.py:finish():624] shutting down handler
2021-11-19 17:50:23,184 INFO    WriterThread:84563 [datastore.py:close():258] close: /home/mansour/Music/OtherWork/TextBPN/wandb/run-20211119_174948-20qk9gpt/run-20qk9gpt.wandb
2021-11-19 17:50:27,120 ERROR   SenderThread:84563 [retry.py:__call__():111] Retry attempt failed:
Traceback (most recent call last):
  File "/home/mansour/anaconda3/envs/v2/lib/python3.7/site-packages/urllib3/connection.py", line 170, in _new_conn
    (self._dns_host, self.port), self.timeout, **extra_kw
  File "/home/mansour/anaconda3/envs/v2/lib/python3.7/site-packages/urllib3/util/connection.py", line 96, in create_connection
    raise err
  File "/home/mansour/anaconda3/envs/v2/lib/python3.7/site-packages/urllib3/util/connection.py", line 86, in create_connection
    sock.connect(sa)
socket.timeout: timed out

During handling of the above exception, another exception occurred:

Traceback (most recent call last):
  File "/home/mansour/anaconda3/envs/v2/lib/python3.7/site-packages/urllib3/connectionpool.py", line 706, in urlopen
    chunked=chunked,
  File "/home/mansour/anaconda3/envs/v2/lib/python3.7/site-packages/urllib3/connectionpool.py", line 382, in _make_request
    self._validate_conn(conn)
  File "/home/mansour/anaconda3/envs/v2/lib/python3.7/site-packages/urllib3/connectionpool.py", line 1010, in _validate_conn
    conn.connect()
  File "/home/mansour/anaconda3/envs/v2/lib/python3.7/site-packages/urllib3/connection.py", line 353, in connect
    conn = self._new_conn()
  File "/home/mansour/anaconda3/envs/v2/lib/python3.7/site-packages/urllib3/connection.py", line 177, in _new_conn
    % (self.host, self.timeout),
urllib3.exceptions.ConnectTimeoutError: (<urllib3.connection.HTTPSConnection object at 0x7f5bff24cba8>, 'Connection to api.wandb.ai timed out. (connect timeout=10)')

During handling of the above exception, another exception occurred:

Traceback (most recent call last):
  File "/home/mansour/anaconda3/envs/v2/lib/python3.7/site-packages/requests/adapters.py", line 449, in send
    timeout=timeout
  File "/home/mansour/anaconda3/envs/v2/lib/python3.7/site-packages/urllib3/connectionpool.py", line 756, in urlopen
    method, url, error=e, _pool=self, _stacktrace=sys.exc_info()[2]
  File "/home/mansour/anaconda3/envs/v2/lib/python3.7/site-packages/urllib3/util/retry.py", line 573, in increment
    raise MaxRetryError(_pool, url, error or ResponseError(cause))
urllib3.exceptions.MaxRetryError: HTTPSConnectionPool(host='api.wandb.ai', port=443): Max retries exceeded with url: /graphql (Caused by ConnectTimeoutError(<urllib3.connection.HTTPSConnection object at 0x7f5bff24cba8>, 'Connection to api.wandb.ai timed out. (connect timeout=10)'))

During handling of the above exception, another exception occurred:

Traceback (most recent call last):
  File "/home/mansour/anaconda3/envs/v2/lib/python3.7/site-packages/wandb/old/retry.py", line 96, in __call__
    result = self._call_fn(*args, **kwargs)
  File "/home/mansour/anaconda3/envs/v2/lib/python3.7/site-packages/wandb/sdk/internal/internal_api.py", line 124, in execute
    return self.client.execute(*args, **kwargs)
  File "/home/mansour/anaconda3/envs/v2/lib/python3.7/site-packages/wandb/vendor/gql-0.2.0/gql/client.py", line 52, in execute
    result = self._get_result(document, *args, **kwargs)
  File "/home/mansour/anaconda3/envs/v2/lib/python3.7/site-packages/wandb/vendor/gql-0.2.0/gql/client.py", line 60, in _get_result
    return self.transport.execute(document, *args, **kwargs)
  File "/home/mansour/anaconda3/envs/v2/lib/python3.7/site-packages/wandb/vendor/gql-0.2.0/gql/transport/requests.py", line 38, in execute
    request = requests.post(self.url, **post_args)
  File "/home/mansour/anaconda3/envs/v2/lib/python3.7/site-packages/requests/api.py", line 119, in post
    return request('post', url, data=data, json=json, **kwargs)
  File "/home/mansour/anaconda3/envs/v2/lib/python3.7/site-packages/requests/api.py", line 61, in request
    return session.request(method=method, url=url, **kwargs)
  File "/home/mansour/anaconda3/envs/v2/lib/python3.7/site-packages/requests/sessions.py", line 542, in request
    resp = self.send(prep, **send_kwargs)
  File "/home/mansour/anaconda3/envs/v2/lib/python3.7/site-packages/requests/sessions.py", line 655, in send
    r = adapter.send(request, **kwargs)
  File "/home/mansour/anaconda3/envs/v2/lib/python3.7/site-packages/requests/adapters.py", line 504, in send
    raise ConnectTimeout(e, request=request)
requests.exceptions.ConnectTimeout: HTTPSConnectionPool(host='api.wandb.ai', port=443): Max retries exceeded with url: /graphql (Caused by ConnectTimeoutError(<urllib3.connection.HTTPSConnection object at 0x7f5bff24cba8>, 'Connection to api.wandb.ai timed out. (connect timeout=10)'))
2021-11-19 17:51:48,721 INFO    MainThread:84563 [internal.py:handle_exit():78] Internal process exited
